<?xml version="1.0" ?>
<!-- =================================================================================== -->
<!-- |    This document was autogenerated by xacro from jetauto.xacro                  | -->
<!-- |    EDITING THIS FILE BY HAND IS NOT RECOMMENDED                                 | -->
<!-- =================================================================================== -->
<robot name="jetauto">
  <material name="black">
    <color rgba="0.1 0.1 0.1 1.0"/>
  </material>
  <material name="blue">
    <color rgba="0.0 0.0 0.8 1.0"/>
  </material>
  <material name="green">
    <color rgba="0.4 0.9 0.4 1.0"/>
  </material>
  <material name="gray">
    <color rgba="0.7 0.7 0.7 1.0"/>
  </material>
  <material name="darkgray">
    <color rgba="0.3 0.3 0.3 1.0"/>
  </material>
  <material name="red">
    <color rgba="0.8 0.0 0.0 1.0"/>
  </material>
  <material name="white">
    <color rgba="1.0 1.0 1.0 1.0"/>
  </material>
  <material name="yellow">
    <color rgba="0.8 0.8 0.0 1.0"/>
  </material>
  <link name="imu_link"/>
  <joint name="imu_joint" type="fixed">
    <origin rpy="0 0 3.141592653589793" xyz="-0.08489999999999998 0 0.080963557909225"/>
    <parent link="base_link"/>
    <child link="imu_link"/>
  </joint>
  <link name="lidar_link">
    <inertial>
      <origin rpy="0 0 0" xyz="-0.0157049024536227 0.000340793431659825 -0.0214732100882973"/>
      <mass value="0.0522535578752524"/>
      <inertia ixx="1.4542908499666E-05" ixy="4.8193721668021E-08" ixz="2.30575406031324E-07" iyy="1.85618648837978E-05" iyz="-1.29750110413905E-08" izz="3.10574357987674E-05"/>
    </inertial>
    <visual>
      <origin rpy="0 0 0" xyz="0 0 0"/>
      <geometry>
        <mesh filename="package://jetauto_description/meshes/lidar_link.stl"/>
      </geometry>
      <material name="black"/>
    </visual>
    <collision>
      <origin rpy="0 0 0" xyz="0 0 0"/>
      <geometry>
        <mesh filename="package://jetauto_description/meshes/lidar_link.stl"/>
      </geometry>
    </collision>
  </link>
  <joint name="lidar_joint" type="fixed">
    <origin rpy="0 0 0" xyz="0.0959394346777203 -1.03974386779226E-05 0.128396206697751"/>
    <parent link="base_link"/>
    <child link="lidar_link"/>
    <axis xyz="0 0 0"/>
  </joint>
  <link name="lidar_frame"/>
  <joint name="lidar_frame_joint" type="fixed">
    <origin rpy="0 0 0" xyz="0 0 0"/>
    <parent link="lidar_link"/>
    <child link="lidar_frame"/>
  </joint>
  <link name="base_footprint"/>
  <joint name="base_joint" type="fixed">
    <parent link="base_footprint"/>
    <child link="base_link"/>
    <origin rpy="0 0 0" xyz="0.0 0.0 0"/>
  </joint>
  <link name="base_link">
    <inertial>
      <mass value="1.6"/>
      <inertia ixx="0.004492333666666667" ixy="0" ixz="0" iyy="0.013450200333333334" iyz="0" izz="0.014564533333333332"/>
    </inertial>
    <visual>
      <origin rpy="0 0 0" xyz="0 0 0"/>
      <geometry>
        <mesh filename="package://jetauto_description/meshes/pro/base_link.stl"/>
      </geometry>
      <material name="green"/>
    </visual>
    <collision>
      <origin rpy="0 0 0" xyz="0.0003999999999999837 0 0.08684214"/>
      <geometry>
        <box size="0.297 0.145 0.11255"/>
      </geometry>
    </collision>
  </link>
  <link name="back_shell_link">
    <inertial>
      <origin rpy="0 0 0" xyz="-1.22838595456587E-05 0.00218574826309681 -0.0500522861933898"/>
      <mass value="0.0663478534899862"/>
      <inertia ixx="5.65277934912267E-05" ixy="-5.13394387877366E-11" ixz="-4.07561372273553E-11" iyy="4.33740893441632E-05" iyz="-5.43059341238134E-06" izz="6.86642544694324E-05"/>
    </inertial>
    <visual>
      <origin rpy="0 0 0" xyz="0 0 0"/>
      <geometry>
        <mesh filename="package://jetauto_description/meshes/back_shell_link.stl"/>
      </geometry>
      <material name="black">
      </material>
    </visual>
    <collision>
      <origin rpy="0 0 0" xyz="0 0 0"/>
      <geometry>
        <mesh filename="package://jetauto_description/meshes/back_shell_link.stl"/>
      </geometry>
    </collision>
  </link>
  <joint name="back_shell_joint" type="fixed">
    <origin rpy="-3.1416 0 1.5708" xyz="-0.076481 0 0.082796"/>
    <parent link="base_link"/>
    <child link="back_shell_link"/>
    <axis xyz="0 0 0"/>
  </joint>
  <link name="wheel_right_front_link">
    <inertial>
      <mass value="0.1"/>
      <inertia ixx="7.449490750000001e-05" ixy="0" ixz="0" iyy="7.449490750000001e-05" iyz="0" izz="0.00012005000000000002"/>
    </inertial>
    <visual>
      <origin rpy="0 0 0" xyz="0 0 0"/>
      <geometry>
        <mesh filename="package://jetauto_description/meshes/wheel_right_front_link.stl"/>
      </geometry>
      <material name="black"/>
    </visual>
    <collision>
      <origin rpy="0 0 0" xyz="0 0 0.020835"/>
      <geometry>
        <cylinder length="0.04167" radius="0.049"/>
      </geometry>
    </collision>
  </link>
  <joint name="wheel_right_front_joint" type="fixed">
    <origin rpy="1.5708 1.5708 0" xyz="0.097397 -0.086125 0.04508"/>
    <parent link="base_link"/>
    <child link="wheel_right_front_link"/>
  </joint>
  <link name="wheel_left_front_link">
    <inertial>
      <mass value="0.1"/>
      <inertia ixx="7.449490750000001e-05" ixy="0" ixz="0" iyy="7.449490750000001e-05" iyz="0" izz="0.00012005000000000002"/>
    </inertial>
    <visual>
      <origin rpy="0 0 0" xyz="0 0 0"/>
      <geometry>
        <mesh filename="package://jetauto_description/meshes/wheel_left_front_link.stl"/>
      </geometry>
      <material name="black"/>
    </visual>
    <collision>
      <origin rpy="0 0 0" xyz="0 0 -0.020835"/>
      <geometry>
        <cylinder length="0.04167" radius="0.049"/>
      </geometry>
    </collision>
  </link>
  <joint name="wheel_left_front_joint" type="fixed">
    <origin rpy="1.5708 1.5708 0" xyz="0.097397 0.086125 0.04508"/>
    <parent link="base_link"/>
    <child link="wheel_left_front_link"/>
  </joint>
  <link name="wheel_right_back_link">
    <inertial>
      <mass value="0.1"/>
      <inertia ixx="7.449490750000001e-05" ixy="0" ixz="0" iyy="7.449490750000001e-05" iyz="0" izz="0.00012005000000000002"/>
    </inertial>
    <visual>
      <origin rpy="0 0 0" xyz="0 0 0"/>
      <geometry>
        <mesh filename="package://jetauto_description/meshes/wheel_right_back_link.stl"/>
      </geometry>
      <material name="black"/>
    </visual>
    <collision>
      <origin rpy="0 0 0" xyz="0 0 0.020835"/>
      <geometry>
        <cylinder length="0.04167" radius="0.049"/>
      </geometry>
    </collision>
  </link>
  <joint name="wheel_right_back_joint" type="fixed">
    <origin rpy="1.5708 1.5708 0" xyz="-0.097397 -0.086125 0.04508"/>
    <parent link="base_link"/>
    <child link="wheel_right_back_link"/>
  </joint>
  <link name="wheel_left_back_link">
    <inertial>
      <mass value="0.1"/>
      <inertia ixx="7.449490750000001e-05" ixy="0" ixz="0" iyy="7.449490750000001e-05" iyz="0" izz="0.00012005000000000002"/>
    </inertial>
    <visual>
      <origin rpy="0 0 0" xyz="0 0 0"/>
      <geometry>
        <mesh filename="package://jetauto_description/meshes/wheel_left_back_link.stl"/>
      </geometry>
      <material name="black"/>
    </visual>
    <collision>
      <origin rpy="0 0 0" xyz="0 0 -0.020835"/>
      <geometry>
        <cylinder length="0.04167" radius="0.049"/>
      </geometry>
    </collision>
  </link>
  <joint name="wheel_left_back_joint" type="fixed">
    <origin rpy="1.5708 1.5708 0" xyz="-0.097397 0.086125 0.04508"/>
    <parent link="base_link"/>
    <child link="wheel_left_back_link"/>
  </joint>
  <link name="mic_link">
    <inertial>
      <origin rpy="0 0 0" xyz="7.37972827624667E-07 0.000380767498086923 -0.0010743560446495"/>
      <mass value="0.0234232570822793"/>
      <inertia ixx="1.59705800233789E-05" ixy="-5.64325349754072E-11" ixz="8.96027229707658E-11" iyy="2.23652963143563E-05" iyz="6.01204669252721E-08" izz="3.74624298483869E-05"/>
    </inertial>
    <visual>
      <origin rpy="0 0 0" xyz="0 0 0"/>
      <geometry>
        <mesh filename="package://jetauto_description/meshes/mic_link.stl"/>
      </geometry>
      <material name="black"/>
    </visual>
    <collision>
      <origin rpy="0 0 0" xyz="0 0 0"/>
      <geometry>
        <mesh filename="package://jetauto_description/meshes/mic_link.stl"/>
      </geometry>
    </collision>
  </link>
  <joint name="mic_joint" type="fixed">
    <origin rpy="0 0 1.5708" xyz="-0.079228 -1.5532E-05 0.15861"/>
    <parent link="base_link"/>
    <child link="mic_link"/>
    <axis xyz="0 0 0"/>
  </joint>
  <link name="speaker_link">
    <inertial>
      <origin rpy="0 0 0" xyz="0 0 0"/>
      <mass value="0"/>
      <inertia ixx="0" ixy="0" ixz="0" iyy="0" iyz="0" izz="0"/>
    </inertial>
    <visual>
      <origin rpy="0 0 0" xyz="0 0 0"/>
      <geometry>
        <mesh filename="package://jetauto_description/meshes/speaker_link.stl"/>
      </geometry>
      <material name="black"/>
    </visual>
    <collision>
      <origin rpy="0 0 0" xyz="0 0 0"/>
      <geometry>
        <mesh filename="package://jetauto_description/meshes/speaker_link.stl"/>
      </geometry>
    </collision>
  </link>
  <joint name="speaker_joint" type="fixed">
    <origin rpy="0 0 0" xyz="-0.130292759618243 0 0.0549589364206024"/>
    <parent link="base_link"/>
    <child link="speaker_link"/>
    <axis xyz="0 0 0"/>
  </joint>
  <link name="link1">
    <inertial>
      <origin xyz="-0.000559793370378037 1.72705471198076E-05 0.0134151597525313"/>
      <mass value="0.00001"/>
      <inertia ixx="10" ixy="0" ixz="0" iyy="10" iyz="0" izz="10"/>
    </inertial>
    <visual>
      <origin rpy="0 0 0" xyz="0 0 0"/>
      <geometry>
        <mesh filename="package://jetauto_description/meshes/pro/arm/link1.stl"/>
      </geometry>
      <material name="green"/>
    </visual>
    <collision>
      <origin rpy="0 0 0" xyz="0 0 0"/>
      <geometry>
        <mesh filename="package://jetauto_description/meshes/pro/arm/link1.stl"/>
      </geometry>
    </collision>
  </link>
  <joint name="joint1" type="revolute">
    <origin rpy="0 0 -1.5707963267948966" xyz="0.0230930273357735 0 0.156176218742268"/>
    <parent link="base_link"/>
    <child link="link1"/>
    <axis xyz="0 0 -1"/>
    <limit effort="1000" lower="-2.09" upper="2.09" velocity="10"/>
  </joint>
  <link name="servo_link">
    <inertial>
      <origin rpy="0 0 0" xyz="-0.0239032469871357 4.14030477700056E-05 0.0069522010024724"/>
      <mass value="0.0116329343814783"/>
      <inertia ixx="2.04910461922326E-06" ixy="9.79840941033059E-11" ixz="-1.98663153836453E-08" iyy="1.75975521005813E-06" iyz="2.48825289975981E-13" izz="5.57276416756103E-07"/>
    </inertial>
    <visual>
      <origin rpy="0 0 0" xyz="0 0 0"/>
      <geometry>
        <mesh filename="package://jetauto_description/meshes/pro/arm/servo_link.stl"/>
      </geometry>
      <material name="black"/>
    </visual>
    <collision>
      <origin rpy="0 0 0" xyz="0 0 0"/>
      <geometry>
        <mesh filename="package://jetauto_description/meshes/pro/arm/servo_link.stl"/>
      </geometry>
    </collision>
  </link>
  <joint name="servo_joint" type="fixed">
    <origin rpy="0 0 0" xyz="0 0 0"/>
    <parent link="link1"/>
    <child link="servo_link"/>
    <axis xyz="0 0 0"/>
  </joint>
  <link name="link2">
    <inertial>
      <origin rpy="0 0 0" xyz="-0.000379251666598135 -0.000106953148182737 0.0722671401198526"/>
      <mass value="0.00001"/>
      <inertia ixx="10" ixy="0" ixz="0" iyy="10" iyz="0" izz="10"/>
    </inertial>
    <visual>
      <origin rpy="0 0 0" xyz="0 0 0"/>
      <geometry>
        <mesh filename="package://jetauto_description/meshes/pro/arm/link2.stl"/>
      </geometry>
      <material name="green"/>
    </visual>
    <collision>
      <origin rpy="0 0 0" xyz="0 0 0"/>
      <geometry>
        <mesh filename="package://jetauto_description/meshes/pro/arm/link2.stl"/>
      </geometry>
    </collision>
  </link>
  <joint name="joint2" type="revolute">
    <origin rpy="0 0 0" xyz="0 1.11027258797025E-05 0.0339293740283087"/>
    <parent link="servo_link"/>
    <child link="link2"/>
    <axis xyz="-1 0 0"/>
    <limit effort="1000" lower="-1.8326" upper="1.8326" velocity="10"/>
  </joint>
  <link name="link3">
    <inertial>
      <origin rpy="0 0 0" xyz="-0.00070372 -0.00019138 0.072342"/>
      <mass value="0.00001"/>
      <inertia ixx="10" ixy="0" ixz="0" iyy="10" iyz="0" izz="10"/>
    </inertial>
    <visual>
      <origin rpy="0 0 0" xyz="0 0 0"/>
      <geometry>
        <mesh filename="package://jetauto_description/meshes/pro/arm/link3.stl"/>
      </geometry>
      <material name="green"/>
    </visual>
    <collision>
      <origin rpy="0 0 0" xyz="0 0 0"/>
      <geometry>
        <mesh filename="package://jetauto_description/meshes/pro/arm/link3.stl"/>
      </geometry>
    </collision>
  </link>
  <joint name="joint3" type="revolute">
    <origin rpy="0 0 0" xyz="0 6.1876E-05 0.12934"/>
    <parent link="link2"/>
    <child link="link3"/>
    <axis xyz="-1 0 0"/>
    <limit effort="1000" lower="-2.09" upper="2.09" velocity="10"/>
  </joint>
  <link name="gripper_servo_link">
    <inertial>
      <origin rpy="0 0 0" xyz="0.00173398274658465 0.0143803550122597 0.0668818334351561"/>
      <mass value="0.0174988102544488"/>
      <inertia ixx="1.57024155329016E-06" ixy="2.76817630588513E-08" ixz="2.23194266007272E-08" iyy="4.12618454370932E-06" iyz="3.03828124784084E-10" izz="3.2611413740062E-06"/>
    </inertial>
    <visual>
      <origin rpy="0 0 0" xyz="0 0 0"/>
      <geometry>
        <mesh filename="package://jetauto_description/meshes/pro/arm/gripper_servo_link.stl"/>
      </geometry>
      <material name="black"/>
    </visual>
    <collision>
      <origin rpy="0 0 0" xyz="0 0 0"/>
      <geometry>
        <mesh filename="package://jetauto_description/meshes/pro/arm/gripper_servo_link.stl"/>
      </geometry>
    </collision>
  </link>
  <joint name="gripper_servo_joint" type="fixed">
    <origin rpy="0 0 0" xyz="0 0 0"/>
    <parent link="link4"/>
    <child link="gripper_servo_link"/>
    <axis xyz="0 0 0"/>
  </joint>
  <link name="link4">
    <inertial>
      <origin rpy="0 0 0" xyz="-0.00163514073939064 -1.93455562591538E-06 0.0167299921199148"/>
      <mass value="0.00001"/>
      <inertia ixx="10" ixy="0" ixz="0" iyy="10" iyz="0" izz="10"/>
    </inertial>
    <visual>
      <origin rpy="0 0 0" xyz="0 0 0"/>
      <geometry>
        <mesh filename="package://jetauto_description/meshes/pro/arm/link4.stl"/>
      </geometry>
      <material name="green"/>
    </visual>
    <collision>
      <origin rpy="0 0 0" xyz="0 0 0"/>
      <geometry>
        <mesh filename="package://jetauto_description/meshes/pro/arm/link4.stl"/>
      </geometry>
    </collision>
  </link>
  <joint name="joint4" type="revolute">
    <origin rpy="0 0 0" xyz="0 1.45460570627753E-05 0.129394452413502"/>
    <parent link="link3"/>
    <child link="link4"/>
    <axis xyz="-1 0 0"/>
    <limit effort="1000" lower="-2.09" upper="2.09" velocity="10"/>
  </joint>
  <!-- end effector link -->
  <link name="end_effector_link"/>
  <joint name="end_effector_joint" type="fixed">
    <origin rpy="0 0 0" xyz="0 0 0.14"/>
    <parent link="link4"/>
    <child link="end_effector_link"/>
  </joint>
  <link name="r_link">
    <inertial>
      <origin rpy="0 0 0" xyz="0.000541257829657527 -0.00150000000696238 0.00625150798228247"/>
      <mass value="0.00001"/>
      <inertia ixx="10" ixy="0" ixz="0" iyy="10" iyz="0" izz="10"/>
    </inertial>
    <visual>
      <origin rpy="0 0 0" xyz="0 0 0"/>
      <geometry>
        <mesh filename="package://jetauto_description/meshes/pro/gripper/r_link.stl"/>
      </geometry>
      <material name="black"/>
    </visual>
    <collision>
      <origin rpy="0 0 0" xyz="0 0 0"/>
      <geometry>
        <mesh filename="package://jetauto_description/meshes/pro/gripper/r_link.stl"/>
      </geometry>
    </collision>
  </link>
  <joint name="r_joint" type="revolute">
    <origin rpy="0 0 -3.141592653589793" xyz="0.012589 -0.0074982 0.068412"/>
    <parent link="gripper_servo_link"/>
    <child link="r_link"/>
    <axis xyz="0 -1 0"/>
    <limit effort="1000" lower="-1.57" upper="1.57" velocity="2"/>
  </joint>
  <link name="l_link">
    <inertial>
      <origin rpy="0 0 0" xyz="-0.0004115 -0.0015023 0.0058059"/>
      <mass value="0.00001"/>
      <inertia ixx="10" ixy="0" ixz="0" iyy="10" iyz="0" izz="10"/>
    </inertial>
    <visual>
      <origin rpy="0 0 0" xyz="0 0 0"/>
      <geometry>
        <mesh filename="package://jetauto_description/meshes/pro/gripper/l_link.stl"/>
      </geometry>
      <material name="black"/>
    </visual>
    <collision>
      <origin rpy="0 0 0" xyz="0 0 0"/>
      <geometry>
        <mesh filename="package://jetauto_description/meshes/pro/gripper/l_link.stl"/>
      </geometry>
    </collision>
  </link>
  <joint name="l_joint" type="revolute">
    <origin rpy="0 0 -3.141592653589793" xyz="-0.015411 -0.0075168 0.06841"/>
    <parent link="gripper_servo_link"/>
    <child link="l_link"/>
    <axis xyz="0 -1 0"/>
    <limit effort="1000" lower="-1.57" upper="1.57" velocity="2"/>
    <mimic joint="r_joint" multiplier="-1" offset="0"/>
  </joint>
  <link name="r_in_link">
    <inertial>
      <origin rpy="0 0 0" xyz="-1.7319E-09 -0.006 0.0145"/>
      <mass value="0.00001"/>
      <inertia ixx="10" ixy="0" ixz="0" iyy="10" iyz="0" izz="10"/>
    </inertial>
    <visual>
      <origin rpy="0 0 0" xyz="0 0 0"/>
      <geometry>
        <mesh filename="package://jetauto_description/meshes/pro/gripper/r_in_link.stl"/>
      </geometry>
      <material name="black"/>
    </visual>
    <collision>
      <origin rpy="0 0 0" xyz="0 0 0"/>
      <geometry>
        <mesh filename="package://jetauto_description/meshes/pro/gripper/r_in_link.stl"/>
      </geometry>
    </collision>
  </link>
  <joint name="r_in_joint" type="revolute">
    <origin rpy="0 0 3.141592653589793" xyz="0.0035253 -0.0075039 0.087368"/>
    <parent link="gripper_servo_link"/>
    <child link="r_in_link"/>
    <axis xyz="0 1 0"/>
    <mimic joint="r_joint" multiplier="-1" offset="0"/>
    <limit effort="1000" lower="-1.57" upper="1.57" velocity="2"/>
  </joint>
  <link name="r_out_link">
    <inertial>
      <origin rpy="0 0 0" xyz="-0.0013784 -0.0060519 0.0096418"/>
      <mass value="0.00001"/>
      <inertia ixx="10" ixy="0" ixz="0" iyy="10" iyz="0" izz="10"/>
    </inertial>
    <visual>
      <origin rpy="0 0 0" xyz="0 0 0"/>
      <geometry>
        <mesh filename="package://jetauto_description/meshes/pro/gripper/r_out_link.stl"/>
      </geometry>
      <material name="black"/>
    </visual>
    <collision>
      <origin rpy="0 0 0" xyz="0 0 0"/>
      <geometry>
        <mesh filename="package://jetauto_description/meshes/pro/gripper/r_out_link.stl"/>
      </geometry>
    </collision>
  </link>
  <joint name="r_out_joint" type="revolute">
    <origin rpy="0 0 0" xyz="0 0 0.029"/>
    <parent link="r_in_link"/>
    <child link="r_out_link"/>
    <axis xyz="0 1 0"/>
    <mimic joint="r_joint" multiplier="1" offset="0"/>
    <limit effort="1000" lower="-1.57" upper="1.57" velocity="2"/>
  </joint>
  <link name="l_in_link">
    <inertial>
      <origin rpy="0 0 0" xyz="-1.7319E-09 -0.006 0.0145"/>
      <mass value="0.00001"/>
      <inertia ixx="10" ixy="0" ixz="0" iyy="10" iyz="0" izz="10"/>
    </inertial>
    <visual>
      <origin rpy="0 0 0" xyz="0 0 0"/>
      <geometry>
        <mesh filename="package://jetauto_description/meshes/pro/gripper/l_in_link.stl"/>
      </geometry>
      <material name="black"/>
    </visual>
    <collision>
      <origin rpy="0 0 0" xyz="0 0 0"/>
      <geometry>
        <mesh filename="package://jetauto_description/meshes/pro/gripper/l_in_link.stl"/>
      </geometry>
    </collision>
  </link>
  <joint name="l_in_joint" type="revolute">
    <origin rpy="0 0 -3.141592653589793" xyz="-0.0063602 -0.0075039 0.087368"/>
    <parent link="gripper_servo_link"/>
    <child link="l_in_link"/>
    <axis xyz="0 -1 0"/>
    <mimic joint="r_joint" multiplier="-1" offset="0"/>
    <limit effort="1000" lower="-1.57" upper="1.57" velocity="2"/>
  </joint>
  <link name="l_out_link">
    <inertial>
      <origin rpy="0 0 0" xyz="0.0013784 -0.0060519 0.0096418"/>
      <mass value="0.00001"/>
      <inertia ixx="10" ixy="0" ixz="0" iyy="10" iyz="0" izz="10"/>
    </inertial>
    <visual>
      <origin rpy="0 0 0" xyz="0 0 0"/>
      <geometry>
        <mesh filename="package://jetauto_description/meshes/pro/gripper/l_out_link.stl"/>
      </geometry>
      <material name="black"/>
    </visual>
    <collision>
      <origin rpy="0 0 0" xyz="0 0 0"/>
      <geometry>
        <mesh filename="package://jetauto_description/meshes/pro/gripper/l_out_link.stl"/>
      </geometry>
    </collision>
  </link>
  <joint name="l_out_joint" type="revolute">
    <origin rpy="0 0 0" xyz="0 0 0.029"/>
    <parent link="l_in_link"/>
    <child link="l_out_link"/>
    <axis xyz="0 -1 0"/>
    <mimic joint="r_joint" multiplier="1" offset="0"/>
    <limit effort="1000" lower="-1.57" upper="1.57" velocity="2"/>
  </joint>
  <link name="usb_cam_link">
    <inertial>
      <origin rpy="0 0 0" xyz="-1.436E-07 0.0030469 -0.012971"/>
      <mass value="0.00001"/>
      <inertia ixx="10" ixy="0" ixz="0" iyy="10" iyz="0" izz="10"/>
    </inertial>
    <visual>
      <origin rpy="0 0 0" xyz="0 0 0"/>
      <geometry>
        <mesh filename="package://jetauto_description/meshes/pro/usb_cam_link.stl"/>
      </geometry>
      <material name="black"/>
    </visual>
    <collision>
      <origin rpy="0 0 0" xyz="0 0 0"/>
      <geometry>
        <mesh filename="package://jetauto_description/meshes/pro/usb_cam_link.stl"/>
      </geometry>
    </collision>
  </link>
  <joint name="usb_cam_joint" type="fixed">
    <origin rpy="0 0 0" xyz="-0.0014233 -0.042451 0.050633"/>
    <parent link="link4"/>
    <child link="usb_cam_link"/>
    <axis xyz="0 0 0"/>
  </joint>
  <link name="screen_link">
    <inertial>
      <mass value="0.5"/>
      <inertia ixx="0.0020354166666666667" ixy="0" ixz="0" iyy="0.0007768854166666667" iyz="0" izz="0.0012935520833333332"/>
    </inertial>
    <visual>
      <origin rpy="0 0 0" xyz="0 0 0"/>
      <geometry>
        <mesh filename="package://jetauto_description/meshes/pro/screen_link.stl"/>
      </geometry>
      <material name="black"/>
    </visual>
    <collision>
      <origin rpy="0 0 0" xyz="-0.01025 0 0"/>
      <geometry>
        <box size="0.0205 0.175 0.135"/>
      </geometry>
    </collision>
  </link>
  <joint name="screen_joint" type="fixed">
    <origin rpy="0 0 0" xyz="-0.14644 0.0024785 0.25477"/>
    <parent link="base_link"/>
    <child link="screen_link"/>
    <axis xyz="0 0 0"/>
  </joint>
  <link name="camera_link">
    <inertial>
      <mass value="0.2"/>
      <inertia ixx="8.501666666666667e-05" ixy="0" ixz="0" iyy="0.000493806" iyz="0" izz="0.0004921226666666666"/>
    </inertial>
    <visual>
      <origin rpy="0 0 0" xyz="0 0 0.08"/>
      <geometry>
        <mesh filename="package://jetauto_description/meshes/pro/depth_camera_link.stl"/>
      </geometry>
      <material name="black"/>
    </visual>
    <collision>
      <origin rpy="-1.5707963267948966 0 1.5707963267948966" xyz="0 0 -0.010000000000000002"/>
      <geometry>
        <box size="0.1644 0.05 0.051"/>
      </geometry>
    </collision>
  </link>
  <joint name="camera_joint" type="fixed">
    <origin rpy="0 0 0" xyz="-0.13068 0 0.43671"/>
    <parent link="base_link"/>
    <child link="camera_link"/>
    <axis xyz="0 0 0"/>
  </joint>
  <link name="camera_frame"/>
  <joint name="camera_joint_sim" type="fixed">
    <origin rpy="-1.5707963267948966 0 -1.5707963267948966" xyz="0 0 0"/>
    <parent link="camera_link"/>
    <child link="camera_frame"/>
  </joint>
  <link name="aerial_left_link">
    <inertial>
      <mass value="0.1"/>
      <inertia ixx="0.00010133958333333334" ixy="0" ixz="0" iyy="0.00010133958333333334" iyz="0" izz="1.0124999999999998e-06"/>
    </inertial>
    <collision>
      <origin rpy="0 0 0" xyz="-0.115 0.038 0.20"/>
      <geometry>
        <cylinder length="0.11" radius="0.0045"/>
      </geometry>
    </collision>
  </link>
  <joint name="aerial_left_joint" type="fixed">
    <parent link="base_link"/>
    <child link="aerial_left_link"/>
    <origin rpy="0 0 0" xyz="0 0 0"/>
  </joint>
  <link name="aerial_right_link">
    <inertial>
      <mass value="0.1"/>
      <inertia ixx="0.00010133958333333334" ixy="0" ixz="0" iyy="0.00010133958333333334" iyz="0" izz="1.0124999999999998e-06"/>
    </inertial>
    <collision>
      <origin rpy="0 0 0" xyz="-0.115 -0.038 0.20"/>
      <geometry>
        <cylinder length="0.11" radius="0.0045"/>
      </geometry>
    </collision>
  </link>
  <joint name="aerial_right_joint" type="fixed">
    <parent link="base_link"/>
    <child link="aerial_right_link"/>
    <origin rpy="0 0 0" xyz="0 0 0"/>
  </joint>
  <link name="connect_link">
    <inertial>
      <origin rpy="0 0 0" xyz="0 0 0"/>
      <mass value="0"/>
      <inertia ixx="0" ixy="0" ixz="0" iyy="0" iyz="0" izz="0"/>
    </inertial>
    <visual>
      <origin rpy="0 0 0" xyz="0 0 0"/>
      <geometry>
        <mesh filename="package://jetauto_description/meshes/pro/connect_link.stl"/>
      </geometry>
      <material name="black"/>
    </visual>
    <collision>
      <origin rpy="0 0 0" xyz="0 0 0"/>
      <geometry>
        <mesh filename="package://jetauto_description/meshes/pro/connect_link.stl"/>
      </geometry>
    </collision>
  </link>
  <joint name="connect_joint" type="fixed">
    <origin rpy="0 0 1.5708" xyz="-0.13644 0 0.080796"/>
    <parent link="base_link"/>
    <child link="connect_link"/>
    <axis xyz="0 0 0"/>
  </joint>
  <link name="depth_camera_connect_left_link">
    <inertial>
      <mass value="0.1"/>
      <inertia ixx="0.0013366666666666672" ixy="0" ixz="0" iyy="0.0013366666666666672" iyz="0" izz="6.6666666666666675e-06"/>
    </inertial>
    <collision>
      <origin rpy="0 0 0" xyz="-0.136 0.06 0.28"/>
      <geometry>
        <box size="0.02 0.02 0.4"/>
      </geometry>
    </collision>
  </link>
  <joint name="depth_camera_connect_left_joint" type="fixed">
    <parent link="base_link"/>
    <child link="depth_camera_connect_left_link"/>
    <origin rpy="0 0 0" xyz="0 0 0"/>
  </joint>
  <link name="depth_camera_connect_right_link">
    <inertial>
      <mass value="0.1"/>
      <inertia ixx="0.0013366666666666672" ixy="0" ixz="0" iyy="0.0013366666666666672" iyz="0" izz="6.6666666666666675e-06"/>
    </inertial>
    <collision>
      <origin rpy="0 0 0" xyz="-0.136 -0.06 0.28"/>
      <geometry>
        <box size="0.02 0.02 0.4"/>
      </geometry>
    </collision>
  </link>
  <joint name="depth_camera_connect_right_joint" type="fixed">
    <parent link="base_link"/>
    <child link="depth_camera_connect_right_link"/>
    <origin rpy="0 0 0" xyz="0 0 0"/>
  </joint>
  <link name="depth_camera_connect_center_link">
    <inertial>
      <mass value="0.1"/>
      <inertia ixx="8.666666666666668e-05" ixy="0" ixz="0" iyy="6.6666666666666675e-06" iyz="0" izz="8.666666666666668e-05"/>
    </inertial>
    <collision>
      <origin rpy="0 0 0" xyz="-0.136 0 0.47"/>
      <geometry>
        <box size="0.02 0.1 0.02"/>
      </geometry>
    </collision>
  </link>
  <joint name="depth_camera_connect_center_joint" type="fixed">
    <parent link="base_link"/>
    <child link="depth_camera_connect_center_link"/>
    <origin rpy="0 0 0" xyz="0 0 0"/>
  </joint>
</robot>
